Workbook

Sheet BNZ
A1: 12.01 | B1: -0.175079 | C1: =EXP(1/F$2*(B1)) -> 0.74453598 | D1: =EXP((Result!H$2+B1-Result!C$26)/F$2) -> 3.4087851e-05 | E1: ave | F1: =AVERAGE(B:B) -> -0.0027068308 | I1: sample_01_12.210000ns | J1: 12.21 | K1: -1812.2575 | L1: -1796.3778 | M1: -41.215219 | N1: -25.351535 | O1: -0.015999212 | P1: -10.039657 | Q1: =P1 -> -10.039657
A2: 12.02 | B2: -0.38514 | C2: =EXP(1/F$2*(B2)) -> 0.52260463 | D2: =EXP((Result!H$2+B2-Result!C$26)/F$2) -> 2.3926941e-05 | E2: kT(kcal/mol) | F2: 0.5935 | I2: sample_02_13.830000ns | J2: 13.83 | K2: -1832.021 | L2: -1816.1366 | M2: -81.802188 | N2: -65.934991 | O2: -0.017182839 | P2: -10.782394 | Q2: =P2 -> -10.782394
A3: 12.03 | B3: 2.254733 | C3: =EXP(1/F$2*(B3)) -> 44.6585 | D3: =EXP((Result!H$2+B3-Result!C$26)/F$2) -> 0.0020446457 | E3: -TDS | F3: =F2*LN(AVERAGE(C:C)) -> 2.3879178 | G3: =F3 -> 2.3879178 | I3: sample_03_15.860000ns | J3: 15.86 | K3: -1872.3726 | L3: -1856.4859 | M3: -127.5235 | N3: -111.65192 | O3: -0.015145769 | P3: -9.504114 | Q3: =P3 -> -9.504114
A4: 12.04 | B4: 1.33463 | C4: =EXP(1/F$2*(B4)) -> 9.4758337 | D4: =EXP((Result!H$2+B4-Result!C$26)/F$2) -> 0.00043384177 | E4: dH | F4: =AVERAGE(Q:Q) -> -10.724382 | G4: =AVERAGE(P22:P41) -> -9.0980751 | I4: sample_04_17.630000ns | J4: 17.63 | K4: -1920.2706 | L4: -1904.3865 | M4: -175.35685 | N4: -159.44316 | O4: 0.029589786 | P4: 18.567871
A5: 12.05 | B5: 0.814549 | C5: =EXP(1/F$2*(B5)) -> 3.9450036 | D5: =EXP((Result!H$2+B5-Result!C$26)/F$2) -> 0.00018061813 | I5: sample_05_19.550000ns | J5: 19.55 | K5: -2073.7853 | L5: -2060.822 | M5: -383.26347 | N5: -370.34403 | O5: -0.043868473 | P5: -27.527882
A6: 12.06 | B6: -0.815548 | C6: =EXP(1/F$2*(B6)) -> 0.25305888 | D6: =EXP((Result!H$2+B6-Result!C$26)/F$2) -> 1.1586053e-05 | E6: DG | F6: =SUM(F3:F4) -> -8.3364641 | G6: =SUM(G3:G4) -> -6.7101573 | I6: sample_06_21.310000ns | J6: 21.31 | K6: -1812.451 | L6: -1796.5653 | M6: -41.215503 | N6: -25.349798 | O6: -0.019948158 | P6: -12.517658 | Q6: =P6 -> -12.517658
A7: 12.07 | B7: -0.685639 | C7: =EXP(1/F$2*(B7)) -> 0.31497978 | D7: =EXP((Result!H$2+B7-Result!C$26)/F$2) -> 1.4421041e-05 | I7: sample_07_23.480000ns | J7: 23.48 | K7: -1817.3749 | L7: -1801.4865 | M7: -46.296148 | N7: -30.426583 | O7: -0.018879138 | P7: -11.846838 | Q7: =P7 -> -11.846838
A8: 12.08 | B8: 0.544207 | C8: =EXP(1/F$2*(B8)) -> 2.5016368 | D8: =EXP((Result!H$2+B8-Result!C$26)/F$2) -> 0.00011453499 | I8: sample_08_25.290000ns | J8: 25.29 | K8: -1840.4576 | L8: -1824.5791 | M8: -71.640592 | N8: -55.776907 | O8: -0.01483274 | P8: -9.307685 | Q8: =P8 -> -9.307685
A9: 12.09 | B9: 0.113983 | C9: =EXP(1/F$2*(B9)) -> 1.2117338 | D9: =EXP((Result!H$2+B9-Result!C$26)/F$2) -> 5.5478047e-05 | I9: sample_09_26.920000ns | J9: 26.92 | K9: -1663.6686 | L9: -1647.7865 | M9: -31.077453 | N9: -15.210945 | O9: -0.015566598 | P9: -9.768188 | Q9: =P9 -> -9.768188
A10: 12.1 | B10: -0.686259 | C10: =EXP(1/F$2*(B10)) -> 0.31465091 | D10: =EXP((Result!H$2+B10-Result!C$26)/F$2) -> 1.4405984e-05 | E10: =VAR(D:D) -> 0.0026431316 | F10: Var(q) | I10: sample_10_29.150000ns | J10: 29.15 | K10: -1802.1745 | L10: -1786.293 | M10: -31.073692 | N10: -15.210951 | O10: -0.018768465 | P10: -11.777389 | Q10: =P10 -> -11.777389
A11: 12.11 | B11: 2.763463 | C11: =EXP(1/F$2*(B11)) -> 105.2369 | D11: =EXP((Result!H$2+B11-Result!C$26)/F$2) -> 0.0048181684 | I11: sample_11_31.130000ns | J11: 31.13 | K11: -1804.1012 | L11: -1788.2112 | M11: -51.369625 | N11: -35.497313 | O11: -0.017747341 | P11: -11.136625 | Q11: =P11 -> -11.136625
A12: 12.12 | B12: 2.393208 | C12: =EXP(1/F$2*(B12)) -> 56.394066 | D12: =EXP((Result!H$2+B12-Result!C$26)/F$2) -> 0.0025819471 | I12: sample_12_32.890000ns | J12: 32.89 | K12: -1822.0548 | L12: -1806.1753 | M12: -51.364472 | N12: -35.502524 | O12: -0.017539129 | P12: -11.00597 | Q12: =P12 -> -11.00597
A13: 12.13 | B13: 2.292986 | C13: =EXP(1/F$2*(B13)) -> 47.631671 | D13: =EXP((Result!H$2+B13-Result!C$26)/F$2) -> 0.0021807694 | I13: sample_13_34.750000ns | J13: 34.75 | K13: -1795.6429 | L13: -1779.76 | M13: -46.291167 | N13: -30.424332 | O13: -0.016087498 | P13: -10.095057 | Q13: =P13 -> -10.095057
A14: 12.14 | B14: 2.222758 | C14: =EXP(1/F$2*(B14)) -> 42.316172 | D14: =EXP((Result!H$2+B14-Result!C$26)/F$2) -> 0.0019374045 | I14: sample_14_36.630000ns | J14: 36.63 | K14: -1835.1979 | L14: -1819.3098 | M14: -66.593331 | N14: -50.723598 | O14: -0.018427054 | P14: -11.563151 | Q14: =P14 -> -11.563151
A15: 12.15 | B15: -0.65746 | C15: =EXP(1/F$2*(B15)) -> 0.33029553 | D15: =EXP((Result!H$2+B15-Result!C$26)/F$2) -> 1.5122258e-05 | I15: sample_15_38.550000ns | J15: 38.55 | K15: -1796.9303 | L15: -1781.0477 | M15: -26.006572 | N15: -10.140597 | O15: -0.016609562 | P15: -10.422658 | Q15: =P15 -> -10.422658
A16: 12.16 | B16: -0.58769 | C16: =EXP(1/F$2*(B16)) -> 0.37149844 | D16: =EXP((Result!H$2+B16-Result!C$26)/F$2) -> 1.7008693e-05 | I16: sample_16_40.430000ns | J16: 40.43 | K16: -1796.9902 | L16: -1781.1051 | M16: -26.007413 | N16: -10.14079 | O16: -0.018443307 | P16: -11.57335 | Q16: =P16 -> -11.57335
A17: 12.17 | B17: 1.722063 | C17: =EXP(1/F$2*(B17)) -> 18.202125 | D17: =EXP((Result!H$2+B17-Result!C$26)/F$2) -> 0.00083336647 | I17: sample_17_42.420000ns | J17: 42.42 | K17: -1796.9166 | L17: -1781.0311 | M17: -26.009519 | N17: -10.140686 | O17: -0.016636038 | P17: -10.439272 | Q17: =P17 -> -10.439272
A18: 12.18 | B18: -1.018172 | C18: =EXP(1/F$2*(B18)) -> 0.17986687 | D18: =EXP((Result!H$2+B18-Result!C$26)/F$2) -> 8.2350285e-06 | I18: sample_18_44.350000ns | J18: 44.35 | K18: -1796.9485 | L18: -1781.063 | M18: -26.007692 | N18: -10.140555 | O18: -0.018290643 | P18: -11.477552 | Q18: =P18 -> -11.477552
A19: 12.19 | B19: -0.9684 | C19: =EXP(1/F$2*(B19)) -> 0.19560137 | D19: =EXP((Result!H$2+B19-Result!C$26)/F$2) -> 8.9554176e-06 | I19: sample_19_46.070000ns | J19: 46.07 | K19: -1807.2249 | L19: -1791.3392 | M19: -36.156099 | N19: -20.286168 | O19: -0.015769997 | P19: -9.895823 | Q19: =P19 -> -9.895823
A20: 12.2 | B20: -0.538686 | C20: =EXP(1/F$2*(B20)) -> 0.40347417 | D20: =EXP((Result!H$2+B20-Result!C$26)/F$2) -> 1.847267e-05 | I20: sample_20_47.970000ns | J20: 47.97 | K20: -1663.948 | L20: -1648.0666 | M20: -31.076251 | N20: -15.210686 | O20: -0.015753537 | P20: -9.885494 | Q20: =P20 -> -9.885494
A21: 12.21 | B21: -0.069029 | C21: =EXP(1/F$2*(B21)) -> 0.8902007 | D21: =EXP((Result!H$2+B21-Result!C$26)/F$2) -> 4.0756968e-05 | I21: ligand | J21: sample | K21: time_ns | L21: E_protein_ligand_Eh | M21: E_protein_Eh | N21: E_ligand_Eh | O21: DeltaE_Eh | P21: DeltaE_kcal_mol
A22: 12.22 | B22: -0.359404 | C22: =EXP(1/F$2*(B22)) -> 0.5457649 | D22: =EXP((Result!H$2+B22-Result!C$26)/F$2) -> 2.4987312e-05 | I22: BNZ | J22: sample_01_12.210000ns | K22: 12.21 | L22: -1788.7426 | M22: -1772.8651 | N22: -15.86444 | O22: -0.013051785 | P22: -8.190119
A23: 12.23 | B23: 1.710174 | C23: =EXP(1/F$2*(B23)) -> 17.841127 | D23: =EXP((Result!H$2+B23-Result!C$26)/F$2) -> 0.00081683856 | I23: BNZ | J23: sample_02_13.830000ns | K23: 13.83 | L23: -1788.709 | M23: -1772.8268 | N23: -15.867683 | O23: -0.01451402 | P23: -9.107685
A24: 12.24 | B24: 0.989748 | C24: =EXP(1/F$2*(B24)) -> 5.2996785 | D24: =EXP((Result!H$2+B24-Result!C$26)/F$2) -> 0.0002426406 | I24: BNZ | J24: sample_03_15.860000ns | K24: 15.86 | L24: -1788.681 | M24: -1772.7951 | N24: -15.871659 | O24: -0.014226705 | P24: -8.927392
A25: 12.25 | B25: -1.100678 | C25: =EXP(1/F$2*(B25)) -> 0.15652268 | D25: =EXP((Result!H$2+B25-Result!C$26)/F$2) -> 7.1662379e-06 | I25: BNZ | J25: sample_04_17.630000ns | K25: 17.63 | L25: -1788.6977 | M25: -1772.8241 | N25: -15.860849 | O25: -0.012741757 | P25: -7.995573
A26: 12.26 | B26: -3.331141 | C26: =EXP(1/F$2*(B26)) -> 0.003651176 | D26: =EXP((Result!H$2+B26-Result!C$26)/F$2) -> 1.6716552e-07 | I26: BNZ | J26: sample_05_19.550000ns | K26: 19.55 | L26: -1788.7809 | M26: -1772.8986 | N26: -15.866585 | O26: -0.015762837 | P26: -9.89133
A27: 12.27 | B27: -1.271631 | C27: =EXP(1/F$2*(B27)) -> 0.11734975 | D27: =EXP((Result!H$2+B27-Result!C$26)/F$2) -> 5.3727436e-06 | I27: BNZ | J27: sample_06_21.310000ns | K27: 21.31 | L27: -1788.8146 | M27: -1772.9313 | N27: -15.86653 | O27: -0.016769532 | P27: -10.52304
A28: 12.28 | B28: -1.752053 | C28: =EXP(1/F$2*(B28)) -> 0.052231523 | D28: =EXP((Result!H$2+B28-Result!C$26)/F$2) -> 2.3913692e-06 | I28: BNZ | J28: sample_07_23.480000ns | K28: 23.48 | L28: -1788.7266 | M28: -1772.8399 | N28: -15.870505 | O28: -0.016203465 | P28: -10.167828
A29: 12.29 | B29: -1.892402 | C29: =EXP(1/F$2*(B29)) -> 0.041231782 | D29: =EXP((Result!H$2+B29-Result!C$26)/F$2) -> 1.8877568e-06 | I29: BNZ | J29: sample_08_25.290000ns | K29: 25.29 | L29: -1788.6299 | M29: -1772.7533 | N29: -15.864572 | O29: -0.012012697 | P29: -7.538081
A30: 12.3 | B30: 0.517284 | C30: =EXP(1/F$2*(B30)) -> 2.3906903 | D30: =EXP((Result!H$2+B30-Result!C$26)/F$2) -> 0.00010945542 | I30: BNZ | J30: sample_09_26.920000ns | K30: 26.92 | L30: -1649.8862 | M30: -1634.006 | N30: -15.867412 | O30: -0.012778039 | P30: -8.018341
A31: 12.31 | B31: -0.25297 | C31: =EXP(1/F$2*(B31)) -> 0.6529634 | D31: =EXP((Result!H$2+B31-Result!C$26)/F$2) -> 2.989529e-05 | I31: BNZ | J31: sample_10_29.150000ns | K31: 29.15 | L31: -1788.7729 | M31: -1772.8935 | N31: -15.863616 | O31: -0.015804678 | P31: -9.917585
A32: 12.32 | B32: -0.623224 | C32: =EXP(1/F$2*(B32)) -> 0.34990886 | D32: =EXP((Result!H$2+B32-Result!C$26)/F$2) -> 1.6020235e-05 | I32: BNZ | J32: sample_11_31.130000ns | K32: 31.13 | L32: -1788.8974 | M32: -1773.0092 | N32: -15.872925 | O32: -0.015343112 | P32: -9.627948
A33: 12.33 | B33: -1.883483 | C33: =EXP(1/F$2*(B33)) -> 0.041856084 | D33: =EXP((Result!H$2+B33-Result!C$26)/F$2) -> 1.9163399e-06 | I33: BNZ | J33: sample_12_32.890000ns | K33: 32.89 | L33: -1788.7295 | M33: -1772.8516 | N33: -15.862781 | O33: -0.015114407 | P33: -9.484433
... A41: 12.41 | B41: 0.925114 | C41: =EXP(1/F$2*(B41)) -> 4.7528434 | D41: =EXP((Result!H$2+B41-Result!C$26)/F$2) -> 0.00021760429 | I41: BNZ | J41: sample_20_47.970000ns | K41: 47.97 | L41: -1650.1593 | M41: -1634.2795 | N41: -15.866431 | O41: -0.013346169 | P41: -8.374847
A42: 12.42 | B42: -2.444981 | C42: =EXP(1/F$2*(B42)) -> 0.016251057 | D42: =EXP((Result!H$2+B42-Result!C$26)/F$2) -> 7.4403876e-07
A43: 12.43 | B43: -1.435052 | C43: =EXP(1/F$2*(B43)) -> 0.089104293 | D43: =EXP((Result!H$2+B43-Result!C$26)/F$2) -> 4.0795529e-06
A44: 12.44 | B44: 0.864825 | C44: =EXP(1/F$2*(B44)) -> 4.2937519 | D44: =EXP((Result!H$2+B44-Result!C$26)/F$2) -> 0.00019658523
A45: 12.45 | B45: 1.304641 | C45: =EXP(1/F$2*(B45)) -> 9.0089243 | D45: =EXP((Result!H$2+B45-Result!C$26)/F$2) -> 0.00041246478
A46: 12.46 | B46: -0.525561 | C46: =EXP(1/F$2*(B46)) -> 0.41249623 | D46: =EXP((Result!H$2+B46-Result!C$26)/F$2) -> 1.8885736e-05
A47: 12.47 | B47: -2.215803 | C47: =EXP(1/F$2*(B47)) -> 0.023910186 | D47: =EXP((Result!H$2+B47-Result!C$26)/F$2) -> 1.0947045e-06
...

Sheet BZF
A1: 12.01 | B1: 4.407978 | C1: =EXP(1/F$2*(B1)) -> 1680.9092 | D1: =EXP((Result!H$3+B1-Result!C$27)/F$2) -> 0.0066868043 | E1: ave | F1: =AVERAGE(B:B) -> -0.0028972106 | I1: sample_01_12.050000ns | J1: 12.05 | K1: -1815.5235 | L1: -1791.2682 | M1: -44.519546 | N1: -20.288571 | O1: -0.024359009 | P1: -15.285509 | Q1: =P1 -> -15.285509
A2: 12.02 | B2: 0.796013 | C2: =EXP(1/F$2*(B2)) -> 3.8236987 | D2: =EXP((Result!H$3+B2-Result!C$27)/F$2) -> 1.5211008e-05 | E2: kT(kcal/mol) | F2: 0.5935 | I2: sample_02_13.880000ns | J2: 13.88 | K2: -1810.595 | L2: -1786.3499 | M2: -39.431501 | N2: -15.210902 | O2: -0.024418552 | P2: -15.322873 | Q2: =P2 -> -15.322873
A3: 12.03 | B3: -2.145905 | C3: =EXP(1/F$2*(B3)) -> 0.026898677 | D3: =EXP((Result!H$3+B3-Result!C$27)/F$2) -> 1.0700529e-07 | E3: -TDS | F3: =F2*LN(AVERAGE(C:C)) -> 2.6721711 | G3: =F3 -> 2.6721711 | I3: sample_03_15.770000ns | J3: 15.77 | K3: -1815.4076 | L3: -1791.1643 | M3: -44.506607 | N3: -20.287466 | O3: -0.024158299 | P3: -15.159561 | Q3: =P3 -> -15.159561
A4: 12.04 | B4: 1.36216 | C4: =EXP(1/F$2*(B4)) -> 9.925732 | D4: =EXP((Result!H$3+B4-Result!C$27)/F$2) -> 3.9485432e-05 | E4: dH | F4: =AVERAGE(Q:Q) -> -14.889693 | G4: =AVERAGE(P22:P41) -> -12.326935 | I4: sample_04_17.630000ns | J4: 17.63 | K4: -1820.6383 | L4: -1796.3967 | M4: -49.571701 | N4: -25.351602 | O4: -0.02147611 | P4: -13.476462 | Q4: =P4 -> -13.476462
A5: 12.05 | B5: -0.039792 | C5: =EXP(1/F$2*(B5)) -> 0.93515187 | D5: =EXP((Result!H$3+B5-Result!C$27)/F$2) -> 3.7201161e-06 | I5: sample_05_19.520000ns | J5: 19.52 | K5: -1820.5816 | L5: -1796.3288 | M5: -49.587169 | N5: -25.356762 | O5: -0.022398065 | P5: -14.054998 | Q5: =P5 -> -14.054998
A6: 12.06 | B6: 0.108267 | C6: =EXP(1/F$2*(B6)) -> 1.2001196 | D6: =EXP((Result!H$3+B6-Result!C$27)/F$2) -> 4.774181e-06 | E6: DG | F6: =SUM(F3:F4) -> -12.217522 | G6: =SUM(G3:G4) -> -9.654764 | I6: sample_06_21.500000ns | J6: 21.5 | K6: -1840.7129 | L6: -1816.4743 | M6: -69.861135 | N6: -45.644783 | O6: -0.022242985 | P6: -13.957684 | Q6: =P6 -> -13.957684
A7: 12.07 | B7: 2.396322 | C7: =EXP(1/F$2*(B7)) -> 56.690734 | D7: =EXP((Result!H$3+B7-Result!C$27)/F$2) -> 0.00022552071 | I7: sample_07_23.370000ns | J7: 23.37 | K7: -1820.6367 | L7: -1796.3803 | M7: -49.5837 | N7: -25.352938 | O7: -0.025621663 | P7: -16.077836 | Q7: =P7 -> -16.077836
A8: 12.08 | B8: 0.754424 | C8: =EXP(1/F$2*(B8)) -> 3.5649287 | D8: =EXP((Result!H$3+B8-Result!C$27)/F$2) -> 1.4181599e-05 | I8: sample_08_25.170000ns | J8: 25.17 | K8: -1840.834 | L8: -1816.6015 | M8: -69.860054 | N8: -45.650436 | O8: -0.022842981 | P8: -14.334187 | Q8: =P8 -> -14.334187
A9: 12.09 | B9: 0.272578 | C9: =EXP(1/F$2*(B9)) -> 1.5829214 | D9: =EXP((Result!H$3+B9-Result!C$27)/F$2) -> 6.2969999e-06 | I9: sample_09_27.200000ns | J9: 27.2 | K9: -1825.7263 | L9: -1801.4808 | M9: -54.644668 | N9: -30.422296 | O9: -0.023195345 | P9: -14.555299 | Q9: =P9 -> -14.555299
A10: 12.1 | B10: 0.700745 | C10: =EXP(1/F$2*(B10)) -> 3.2566506 | D10: =EXP((Result!H$3+B10-Result!C$27)/F$2) -> 1.2955241e-05 | E10: =VAR(D:D) -> 2.9709367e-05 | F10: Var(q) | I10: sample_10_29.080000ns | J10: 29.08 | K10: -1820.6821 | L10: -1796.4288 | M10: -49.583648 | N10: -25.356642 | O10: -0.026276589 | P10: -16.488808 | Q10: =P10 -> -16.488808
A11: 12.11 | B11: 0.49894 | C11: =EXP(1/F$2*(B11)) -> 2.3179287 | D11: =EXP((Result!H$3+B11-Result!C$27)/F$2) -> 9.2209233e-06 | I11: sample_11_31.050000ns | J11: 31.05 | K11: -1830.8391 | L11: -1806.5917 | M11: -59.733591 | N11: -35.511478 | O11: -0.025268206 | P11: -15.856039 | Q11: =P11 -> -15.856039
A12: 12.12 | B12: -0.662886 | C12: =EXP(1/F$2*(B12)) -> 0.32728961 | D12: =EXP((Result!H$3+B12-Result!C$27)/F$2) -> 1.3019867e-06 | I12: sample_12_32.950000ns | J12: 32.95 | K12: -1815.5535 | L12: -1791.302 | M12: -44.511195 | N12: -20.283916 | O12: -0.024161683 | P12: -15.161685 | Q12: =P12 -> -15.161685
A13: 12.13 | B13: 0.365261 | C13: =EXP(1/F$2*(B13)) -> 1.8504624 | D13: =EXP((Result!H$3+B13-Result!C$27)/F$2) -> 7.3613016e-06 | I13: sample_13_34.600000ns | J13: 34.6 | K13: -1825.7274 | L13: -1801.4801 | M13: -54.660342 | N13: -30.435979 | O13: -0.022921517 | P13: -14.383469 | Q13: =P13 -> -14.383469
A14: 12.14 | B14: -1.676589 | C14: =EXP(1/F$2*(B14)) -> 0.059313504 | D14: =EXP((Result!H$3+B14-Result!C$27)/F$2) -> 2.3595431e-07 | I14: sample_14_36.750000ns | J14: 36.75 | K14: -1841.0938 | L14: -1816.8416 | M14: -69.876935 | N14: -45.647407 | O14: -0.0226702 | P14: -14.225766 | Q14: =P14 -> -14.225766
A15: 12.15 | B15: 0.441551 | C15: =EXP(1/F$2*(B15)) -> 2.10429 | D15: =EXP((Result!H$3+B15-Result!C$27)/F$2) -> 8.3710498e-06 | I15: sample_15_38.570000ns | J15: 38.57 | K15: -1815.4478 | L15: -1791.1933 | M15: -44.516708 | N15: -20.286317 | O15: -0.024074208 | P15: -15.106794 | Q15: =P15 -> -15.106794
A16: 12.16 | B16: -1.2503 | C16: =EXP(1/F$2*(B16)) -> 0.12164413 | D16: =EXP((Result!H$3+B16-Result!C$27)/F$2) -> 4.8391102e-07 | I16: sample_16_40.280000ns | J16: 40.28 | K16: -1815.3789 | L16: -1791.1244 | M16: -44.515932 | N16: -20.286824 | O16: -0.025402548 | P16: -15.94034 | Q16: =P16 -> -15.94034
A17: 12.17 | B17: 0.57786 | C17: =EXP(1/F$2*(B17)) -> 2.6475849 | D17: =EXP((Result!H$3+B17-Result!C$27)/F$2) -> 1.0532325e-05 | I17: sample_17_42.320000ns | J17: 42.32 | K17: -1830.2677 | L17: -1806.0189 | M17: -59.728571 | N17: -35.50283 | O17: -0.023008624 | P17: -14.43813 | Q17: =P17 -> -14.43813
A18: 12.18 | B18: -1.39399 | C18: =EXP(1/F$2*(B18)) -> 0.095487342 | D18: =EXP((Result!H$3+B18-Result!C$27)/F$2) -> 3.7985701e-07 | I18: sample_18_44.060000ns | J18: 44.06 | K18: -1830.8109 | L18: -1806.5759 | M18: -59.720574 | N18: -35.508583 | O18: -0.023008488 | P18: -14.438044 | Q18: =P18 -> -14.438044
A19: 12.19 | B19: 0.604153 | C19: =EXP(1/F$2*(B19)) -> 2.767514 | D19: =EXP((Result!H$3+B19-Result!C$27)/F$2) -> 1.1009413e-05 | I19: sample_19_46.060000ns | J19: 46.06 | K19: -1820.7768 | L19: -1796.5335 | M19: -49.569937 | N19: -25.350838 | O19: -0.024194818 | P19: -15.182478 | Q19: =P19 -> -15.182478
A20: 12.2 | B20: -2.687661 | C20: =EXP(1/F$2*(B20)) -> 0.010796927 | D20: =EXP((Result!H$3+B20-Result!C$27)/F$2) -> 4.2951123e-08 | I20: sample_20_47.620000ns | J20: 47.62 | K20: -1815.6019 | L20: -1791.3566 | M20: -44.512912 | N20: -20.290425 | O20: -0.022864821 | P20: -14.347892 | Q20: =P20 -> -14.347892
A21: 12.21 | B21: -1.429431 | C21: =EXP(1/F$2*(B21)) -> 0.089952203 | D21: =EXP((Result!H$3+B21-Result!C$27)/F$2) -> 3.5783774e-07 | I21: ligand | J21: sample | K21: time_ns | L21: E_protein_ligand_Eh | M21: E_protein_Eh | N21: E_ligand_Eh | O21: DeltaE_Eh | P21: DeltaE_kcal_mol
A22: 12.22 | B22: 0.318822 | C22: =EXP(1/F$2*(B22)) -> 1.7111909 | D22: =EXP((Result!H$3+B22-Result!C$27)/F$2) -> 6.8072673e-06 | I22: BZF | J22: sample_01_12.050000ns | K22: 12.05 | L22: -1796.9717 | M22: -1772.7196 | N22: -24.232044 | O22: -0.02006999 | P22: -12.594109
A23: 12.23 | B23: -0.44289 | C23: =EXP(1/F$2*(B23)) -> 0.47414874 | D23: =EXP((Result!H$3+B23-Result!C$27)/F$2) -> 1.8862052e-06 | I23: BZF | J23: sample_02_13.880000ns | K23: 13.88 | L23: -1797.1681 | M23: -1772.9263 | N23: -24.221841 | O23: -0.019942954 | P23: -12.514393
A24: 12.24 | B24: 1.215399 | C24: =EXP(1/F$2*(B24)) -> 7.7512184 | D24: =EXP((Result!H$3+B24-Result!C$27)/F$2) -> 3.0835026e-05 | I24: BZF | J24: sample_03_15.770000ns | K24: 15.77 | L24: -1796.9364 | M24: -1772.6959 | N24: -24.221183 | O24: -0.019326578 | P24: -12.127611
A25: 12.25 | B25: 0.423687 | C25: =EXP(1/F$2*(B25)) -> 2.0418958 | D25: =EXP((Result!H$3+B25-Result!C$27)/F$2) -> 8.1228404e-06 | I25: BZF | J25: sample_04_17.630000ns | K25: 17.63 | L25: -1797.1275 | M25: -1772.8878 | N25: -24.221721 | O25: -0.017990469 | P25: -11.28919
A26: 12.26 | B26: -0.977998 | C26: =EXP(1/F$2*(B26)) -> 0.19246358 | D26: =EXP((Result!H$3+B26-Result!C$27)/F$2) -> 7.6563697e-07 | I26: BZF | J26: sample_05_19.520000ns | K26: 19.52 | L26: -1797.0382 | M26: -1772.7884 | N26: -24.231602 | O26: -0.018187306 | P26: -11.412707
A27: 12.27 | B27: 1.750337 | C27: =EXP(1/F$2*(B27)) -> 19.09025 | D27: =EXP((Result!H$3+B27-Result!C$27)/F$2) -> 7.5942689e-05 | I27: BZF | J27: sample_06_21.500000ns | K27: 21.5 | L27: -1796.7376 | M27: -1772.5013 | N27: -24.217614 | O27: -0.018654114 | P27: -11.705633
A28: 12.28 | B28: 0.198621 | C28: =EXP(1/F$2*(B28)) -> 1.3974658 | D28: =EXP((Result!H$3+B28-Result!C$27)/F$2) -> 5.5592416e-06 | I28: BZF | J28: sample_07_23.370000ns | K28: 23.37 | L28: -1797.1506 | M28: -1772.8972 | N28: -24.232367 | O28: -0.021012222 | P28: -13.185368
A29: 12.29 | B29: -2.40315 | C29: =EXP(1/F$2*(B29)) -> 0.017437793 | D29: =EXP((Result!H$3+B29-Result!C$27)/F$2) -> 6.9369068e-08 | I29: BZF | J29: sample_08_25.170000ns | K29: 25.17 | L29: -1796.9866 | M29: -1772.7562 | N29: -24.21146 | O29: -0.018937769 | P29: -11.88363
A30: 12.3 | B30: 2.245054 | C30: =EXP(1/F$2*(B30)) -> 43.9361 | D30: =EXP((Result!H$3+B30-Result!C$27)/F$2) -> 0.00017478166 | I30: BZF | J30: sample_09_27.200000ns | K30: 27.2 | L30: -1797.0806 | M30: -1772.8373 | N30: -24.224254 | O30: -0.01898734 | P30: -11.914736
A31: 12.31 | B31: -1.746789 | C31: =EXP(1/F$2*(B31)) -> 0.052696847 | D31: =EXP((Result!H$3+B31-Result!C$27)/F$2) -> 2.0963267e-07 | I31: BZF | J31: sample_10_29.080000ns | K31: 29.08 | L31: -1797.1311 | M31: -1772.8807 | N31: -24.22851 | O31: -0.021918751 | P31: -13.754224
A32: 12.32 | B32: 0.64137 | C32: =EXP(1/F$2*(B32)) -> 2.9466152 | D32: =EXP((Result!H$3+B32-Result!C$27)/F$2) -> 1.1721893e-05 | I32: BZF | J32: sample_11_31.050000ns | K32: 31.05 | L32: -1797.1057 | M32: -1772.8602 | N32: -24.223609 | O32: -0.02186503 | P32: -13.720513
A33: 12.33 | B33: -1.920469 | C33: =EXP(1/F$2*(B33)) -> 0.039327291 | D33: =EXP((Result!H$3+B33-Result!C$27)/F$2) -> 1.5644741e-07 | I33: BZF | J33: sample_12_32.950000ns | K33: 32.95 | L33: -1797.0943 | M33: -1772.8448 | N33: -24.228819 | O33: -0.020681556 | P33: -12.977872
... A41: 12.41 | B41: -1.555687 | C41: =EXP(1/F$2*(B41)) -> 0.072714964 | D41: =EXP((Result!H$3+B41-Result!C$27)/F$2) -> 2.892665e-07 | I41: BZF | J41: sample_20_47.620000ns | K41: 47.62 | L41: -1797.0367 | M41: -1772.7943 | N41: -24.224487 | O41: -0.017947538 | P41: -11.26225
A42: 12.42 | B42: -2.027651 | C42: =EXP(1/F$2*(B42)) -> 0.032829438 | D42: =EXP((Result!H$3+B42-Result!C$27)/F$2) -> 1.3059838e-07
A43: 12.43 | B43: -1.429633 | C43: =EXP(1/F$2*(B43)) -> 0.089921592 | D43: =EXP((Result!H$3+B43-Result!C$27)/F$2) -> 3.5771597e-07
A44: 12.44 | B44: 1.408423 | C44: =EXP(1/F$2*(B44)) -> 10.730391 | D44: =EXP((Result!H$3+B44-Result!C$27)/F$2) -> 4.2686437e-05
A45: 12.45 | B45: 2.566525 | C45: =EXP(1/F$2*(B45)) -> 75.519373 | D45: =EXP((Result!H$3+B45-Result!C$27)/F$2) -> 0.00030042268
A46: 12.46 | B46: -0.115359 | C46: =EXP(1/F$2*(B46)) -> 0.82335265 | D46: =EXP((Result!H$3+B46-Result!C$27)/F$2) -> 3.275369e-06
A47: 12.47 | B47: -0.167215 | C47: =EXP(1/F$2*(B47)) -> 0.75446688 | D47: =EXP((Result!H$3+B47-Result!C$27)/F$2) -> 3.0013354e-06
...

Sheet DEN
A1: 12.01 | B1: 0.615044 | C1: =EXP(1/F$2*(B1)) -> 2.818768 | D1: =EXP((Result!H$4+B1-Result!C$28)/F$2) -> 4.1846495e-06 | E1: ave | F1: =AVERAGE(B:B) -> -0.0035258006 | I1: sample_01_12.080000ns | J1: 12.08 | K1: -1845.1272 | L1: -1821.8052 | M1: -74.03976 | N1: -50.739004 | O1: -0.021207994 | P1: -13.308217 | Q1: =P1 -> -13.308217
A2: 12.02 | B2: -0.638196 | C2: =EXP(1/F$2*(B2)) -> 0.34119225 | D2: =EXP((Result!H$4+B2-Result!C$28)/F$2) -> 5.0652269e-07 | E2: kT(kcal/mol) | F2: 0.5935 | I2: sample_02_13.890000ns | J2: 13.89 | K2: -1828.8415 | L2: -1805.5251 | M2: -58.797074 | N2: -35.50363 | O2: -0.022971856 | P2: -14.415057 | Q2: =P2 -> -14.415057
A3: 12.03 | B3: 0.568451 | C3: =EXP(1/F$2*(B3)) -> 2.6059426 | D3: =EXP((Result!H$4+B3-Result!C$28)/F$2) -> 3.8686959e-06 | E3: -TDS | F3: =F2*LN(AVERAGE(C:C)) -> 3.0385809 | G3: =F3 -> 3.0385809 | I3: sample_03_16.070000ns | J3: 16.07 | K3: -1824.7993 | L3: -1801.4728 | M3: -53.736106 | N3: -30.434069 | O3: -0.024515255 | P3: -15.383555 | Q3: =P3 -> -15.383555
A4: 12.04 | B4: 0.375106 | C4: =EXP(1/F$2*(B4)) -> 1.8814139 | D4: =EXP((Result!H$4+B4-Result!C$28)/F$2) -> 2.7930847e-06 | E4: dH | F4: =AVERAGE(Q:Q) -> -14.261506 | G4: =AVERAGE(P22:P41) -> -11.313754 | I4: sample_04_17.660000ns | J4: 17.66 | K4: -1839.8748 | L4: -1816.553 | M4: -68.946445 | N4: -45.64826 | O4: -0.023547531 | P4: -14.776299 | Q4: =P4 -> -14.776299
A5: 12.05 | B5: -0.548232 | C5: =EXP(1/F$2*(B5)) -> 0.39703651 | D5: =EXP((Result!H$4+B5-Result!C$28)/F$2) -> 5.8942723e-07 | I5: sample_05_19.670000ns | J5: 19.67 | K5: -1845.0675 | L5: -1821.7313 | M5: -74.029992 | N5: -50.716537 | O5: -0.02274117 | P5: -14.2703 | Q5: =P5 -> -14.2703
A6: 12.06 | B6: -1.051616 | C6: =EXP(1/F$2*(B6)) -> 0.17001157 | D6: =EXP((Result!H$4+B6-Result!C$28)/F$2) -> 2.5239353e-07 | E6: DG | F6: =SUM(F3:F4) -> -11.222925 | G6: =SUM(G3:G4) -> -8.2751727 | I6: sample_06_21.270000ns | J6: 21.27 | K6: -1829.9396 | L6: -1806.6176 | M6: -58.801341 | N6: -35.504314 | O6: -0.025003041 | P6: -15.689645 | Q6: =P6 -> -15.689645
A7: 12.07 | B7: 1.214984 | C7: =EXP(1/F$2*(B7)) -> 7.7458003 | D7: =EXP((Result!H$4+B7-Result!C$28)/F$2) -> 1.1499158e-05 | I7: sample_07_23.560000ns | J7: 23.56 | K7: -1829.72 | L7: -1806.3929 | M7: -58.796175 | N7: -35.491849 | O7: -0.022791072 | P7: -14.301613 | Q7: =P7 -> -14.301613
A8: 12.08 | B8: -0.088529 | C8: =EXP(1/F$2*(B8)) -> 0.86142759 | D8: =EXP((Result!H$4+B8-Result!C$28)/F$2) -> 1.2788468e-06 | I8: sample_08_25.250000ns | J8: 25.25 | K8: -1855.1127 | L8: -1831.7909 | M8: -84.158835 | N8: -60.860803 | O8: -0.023779366 | P8: -14.921777 | Q8: =P8 -> -14.921777
A9: 12.09 | B9: 1.037838 | C9: =EXP(1/F$2*(B9)) -> 5.7469769 | D9: =EXP((Result!H$4+B9-Result!C$28)/F$2) -> 8.5317713e-06 | I9: sample_09_27.180000ns | J9: 27.18 | K9: -1830.0028 | L9: -1806.6789 | M9: -58.807416 | N9: -35.50338 | O9: -0.019903865 | P9: -12.489864 | Q9: =P9 -> -12.489864
A10: 12.1 | B10: -0.475845 | C10: =EXP(1/F$2*(B10)) -> 0.44853851 | D10: =EXP((Result!H$4+B10-Result!C$28)/F$2) -> 6.6588539e-07 | E10: =VAR(D:D) -> 3.7086512e-05 | F10: Var(q) | I10: sample_10_29.160000ns | J10: 29.16 | K10: -1958.7035 | L10: -1935.3521 | M10: -235.401 | N10: -212.07324 | O10: -0.023640419 | P10: -14.834587 | Q10: =P10 -> -14.834587
A11: 12.11 | B11: -0.349602 | C11: =EXP(1/F$2*(B11)) -> 0.55485337 | D11: =EXP((Result!H$4+B11-Result!C$28)/F$2) -> 8.2371691e-07 | I11: sample_11_30.940000ns | J11: 30.94 | K11: -1947.7388 | L11: -1924.4174 | M11: -199.65264 | N11: -176.35394 | O11: -0.022724597 | P11: -14.2599 | Q11: =P11 -> -14.2599
A12: 12.12 | B12: -0.283349 | C12: =EXP(1/F$2*(B12)) -> 0.62038167 | D12: =EXP((Result!H$4+B12-Result!C$28)/F$2) -> 9.2099805e-07 | I12: sample_12_32.660000ns | J12: 32.66 | K12: -1943.6893 | L12: -1920.3706 | M12: -206.1284 | N12: -182.82733 | O12: -0.017645882 | P12: -11.072958 | Q12: =P12 -> -11.072958
A13: 12.13 | B13: -2.007072 | C13: =EXP(1/F$2*(B13)) -> 0.033987731 | D13: =EXP((Result!H$4+B13-Result!C$28)/F$2) -> 5.0457057e-08 | I13: sample_13_34.790000ns | J13: 34.79 | K13: -1834.85 | L13: -1811.5292 | M13: -63.865559 | N13: -40.564643 | O13: -0.019800792 | P13: -12.425185 | Q13: =P13 -> -12.425185
A14: 12.14 | B14: -0.980828 | C14: =EXP(1/F$2*(B14)) -> 0.19154803 | D14: =EXP((Result!H$4+B14-Result!C$28)/F$2) -> 2.8436585e-07 | I14: sample_14_36.620000ns | J14: 36.62 | K14: -1824.9901 | L14: -1801.6653 | M14: -53.728272 | N14: -30.426548 | O14: -0.023023112 | P14: -14.447221 | Q14: =P14 -> -14.447221
A15: 12.15 | B15: 0.775409 | C15: =EXP(1/F$2*(B15)) -> 3.6932326 | D15: =EXP((Result!H$4+B15-Result!C$28)/F$2) -> 5.4828505e-06 | I15: sample_15_38.570000ns | J15: 38.57 | K15: -1839.6481 | L15: -1816.3275 | M15: -74.026861 | N15: -50.729245 | O15: -0.023035075 | P15: -14.454728 | Q15: =P15 -> -14.454728
A16: 12.16 | B16: 0.501604 | C16: =EXP(1/F$2*(B16)) -> 2.3283564 | D16: =EXP((Result!H$4+B16-Result!C$28)/F$2) -> 3.4566006e-06 | I16: sample_16_40.560000ns | J16: 40.56 | K16: -1859.3284 | L16: -1836.0153 | M16: -99.376533 | N16: -76.085452 | O16: -0.021936619 | P16: -13.765436 | Q16: =P16 -> -13.765436
A17: 12.17 | B17: 0.287753 | C17: =EXP(1/F$2*(B17)) -> 1.6239164 | D17: =EXP((Result!H$4+B17-Result!C$28)/F$2) -> 2.4108124e-06 | I17: sample_17_42.350000ns | J17: 42.35 | K17: -1829.9689 | L17: -1806.6507 | M17: -58.797796 | N17: -35.501051 | O17: -0.021457027 | P17: -13.464488 | Q17: =P17 -> -13.464488
A18: 12.18 | B18: 0.843894 | C18: =EXP(1/F$2*(B18)) -> 4.1449629 | D18: =EXP((Result!H$4+B18-Result!C$28)/F$2) -> 6.1534745e-06 | I18: sample_18_44.230000ns | J18: 44.23 | K18: -1824.8876 | L18: -1801.5569 | M18: -53.730532 | N18: -30.424042 | O18: -0.024257986 | P18: -15.222116 | Q18: =P18 -> -15.222116
A19: 12.19 | B19: -0.409979 | C19: =EXP(1/F$2*(B19)) -> 0.50118409 | D19: =EXP((Result!H$4+B19-Result!C$28)/F$2) -> 7.4404127e-07 | I19: sample_19_46.120000ns | J19: 46.12 | K19: -1829.6837 | L19: -1806.3501 | M19: -58.805266 | N19: -35.494574 | O19: -0.02292551 | P19: -14.385975 | Q19: =P19 -> -14.385975
A20: 12.2 | B20: -0.383955 | C20: =EXP(1/F$2*(B20)) -> 0.52364912 | D20: =EXP((Result!H$4+B20-Result!C$28)/F$2) -> 7.773921e-07 | I20: sample_20_47.840000ns | J20: 47.84 | K20: -1814.6207 | L20: -1791.2868 | M20: -43.587337 | N20: -20.280981 | O20: -0.027634958 | P20: -17.341198 | Q20: =P20 -> -17.341198
A21: 12.21 | B21: 0.481963 | C21: =EXP(1/F$2*(B21)) -> 2.2525639 | D21: =EXP((Result!H$4+B21-Result!C$28)/F$2) -> 3.3440816e-06 | I21: ligand | J21: sample | K21: time_ns | L21: E_protein_ligand_Eh | M21: E_protein_Eh | N21: E_ligand_Eh | O21: DeltaE_Eh | P21: DeltaE_kcal_mol
A22: 12.22 | B22: 0.307813 | C22: =EXP(1/F$2*(B22)) -> 1.6797421 | D22: =EXP((Result!H$4+B22-Result!C$28)/F$2) -> 2.4936894e-06 | I22: DEN | J22: sample_01_12.080000ns | K22: 12.08 | L22: -1796.1702 | M22: -1772.8506 | N22: -23.302533 | O22: -0.017070446 | P22: -10.711867
A23: 12.23 | B23: -1.626428 | C23: =EXP(1/F$2*(B23)) -> 0.064544459 | D23: =EXP((Result!H$4+B23-Result!C$28)/F$2) -> 9.5820562e-08 | I23: DEN | J23: sample_02_13.890000ns | K23: 13.89 | L23: -1795.0949 | M23: -1771.7813 | N23: -23.295173 | O23: -0.018425395 | P23: -11.56211
A24: 12.24 | B24: 0.039303 | C24: =EXP(1/F$2*(B24)) -> 1.0684643 | D24: =EXP((Result!H$4+B24-Result!C$28)/F$2) -> 1.5862067e-06 | I24: DEN | J24: sample_03_16.070000ns | K24: 16.07 | L24: -1796.1111 | M24: -1772.7881 | N24: -23.303774 | O24: -0.019244957 | P24: -12.076393
A25: 12.25 | B25: -0.234991 | C25: =EXP(1/F$2*(B25)) -> 0.67304639 | D25: =EXP((Result!H$4+B25-Result!C$28)/F$2) -> 9.9918233e-07 | I25: DEN | J25: sample_04_17.660000ns | K25: 17.66 | L25: -1795.8509 | M25: -1772.5316 | N25: -23.299788 | O25: -0.019554985 | P25: -12.270938
A26: 12.26 | B26: -1.73936 | C26: =EXP(1/F$2*(B26)) -> 0.053360613 | D26: =EXP((Result!H$4+B26-Result!C$28)/F$2) -> 7.9217395e-08 | I26: DEN | J26: sample_05_19.670000ns | K26: 19.67 | L26: -1796.0655 | M26: -1772.7317 | N26: -23.315084 | O26: -0.018713676 | P26: -11.743009
A27: 12.27 | B27: -0.58379 | C27: =EXP(1/F$2*(B27)) -> 0.37394766 | D27: =EXP((Result!H$4+B27-Result!C$28)/F$2) -> 5.5515029e-07 | I27: DEN | J27: sample_06_21.270000ns | K27: 21.27 | L27: -1796.1807 | M27: -1772.8618 | N27: -23.298874 | O27: -0.0200652 | P27: -12.591103
A28: 12.28 | B28: -0.868153 | C28: =EXP(1/F$2*(B28)) -> 0.23159426 | D28: =EXP((Result!H$4+B28-Result!C$28)/F$2) -> 3.4381715e-07 | I28: DEN | J28: sample_07_23.560000ns | K28: 23.56 | L28: -1796.0118 | M28: -1772.6875 | N28: -23.306095 | O28: -0.018205019 | P28: -11.423822
A29: 12.29 | B29: 1.04756 | C29: =EXP(1/F$2*(B29)) -> 5.8418923 | D29: =EXP((Result!H$4+B29-Result!C$28)/F$2) -> 8.6726794e-06 | I29: DEN | J29: sample_08_25.250000ns | K29: 25.25 | L29: -1795.9977 | M29: -1772.6789 | N29: -23.299769 | O29: -0.019104647 | P29: -11.988347
A30: 12.3 | B30: -2.846704 | C30: =EXP(1/F$2*(B30)) -> 0.0082588625 | D30: =EXP((Result!H$4+B30-Result!C$28)/F$2) -> 1.2260833e-08 | I30: DEN | J30: sample_09_27.180000ns | K30: 27.18 | L30: -1796.1122 | M30: -1772.7914 | N30: -23.305788 | O30: -0.014968654 | P30: -9.392972
A31: 12.31 | B31: -0.81091 | C31: =EXP(1/F$2*(B31)) -> 0.25504419 | D31: =EXP((Result!H$4+B31-Result!C$28)/F$2) -> 3.7863014e-07 | I31: DEN | J31: sample_10_29.160000ns | K31: 29.16 | L31: -1796.2439 | M31: -1772.9221 | N31: -23.304661 | O31: -0.017153694 | P31: -10.764105
A32: 12.32 | B32: -2.725142 | C32: =EXP(1/F$2*(B32)) -> 0.010136159 | D32: =EXP((Result!H$4+B32-Result!C$28)/F$2) -> 1.5047805e-08 | I32: DEN | J32: sample_11_30.940000ns | K32: 30.94 | L32: -1796.2261 | M32: -1772.9115 | N32: -23.29702 | O32: -0.017575669 | P32: -11.028899
A33: 12.33 | B33: 0.050595 | C33: =EXP(1/F$2*(B33)) -> 1.0889877 | D33: =EXP((Result!H$4+B33-Result!C$28)/F$2) -> 1.616675e-06 | I33: DEN | J33: sample_12_32.660000ns | K33: 32.66 | L33: -1795.9623 | M33: -1772.6459 | N33: -23.300381 | O33: -0.015958216 | P33: -10.013932
... A41: 12.41 | B41: -0.703502 | C41: =EXP(1/F$2*(B41)) -> 0.30564085 | D41: =EXP((Result!H$4+B41-Result!C$28)/F$2) -> 4.5374426e-07 | I41: DEN | J41: sample_20_47.840000ns | K41: 47.84 | L41: -1796.1127 | M41: -1772.7831 | N41: -23.308087 | O41: -0.021477269 | P41: -13.47719
A42: 12.42 | B42: 1.922233 | C42: =EXP(1/F$2*(B42)) -> 25.503323 | D42: =EXP((Result!H$4+B42-Result!C$28)/F$2) -> 3.7861387e-05
A43: 12.43 | B43: -1.912025 | C43: =EXP(1/F$2*(B43)) -> 0.039890818 | D43: =EXP((Result!H$4+B43-Result!C$28)/F$2) -> 5.9220585e-08
A44: 12.44 | B44: 0.50362 | C44: =EXP(1/F$2*(B44)) -> 2.3362788 | D44: =EXP((Result!H$4+B44-Result!C$28)/F$2) -> 3.4683619e-06
A45: 12.45 | B45: 1.239154 | C45: =EXP(1/F$2*(B45)) -> 8.0677555 | D45: =EXP((Result!H$4+B45-Result!C$28)/F$2) -> 1.1977122e-05
A46: 12.46 | B46: 2.054638 | C46: =EXP(1/F$2*(B46)) -> 31.877505 | D46: =EXP((Result!H$4+B46-Result!C$28)/F$2) -> 4.7324286e-05
A47: 12.47 | B47: 2.280042 | C47: =EXP(1/F$2*(B47)) -> 46.604089 | D47: =EXP((Result!H$4+B47-Result!C$28)/F$2) -> 6.9186885e-05
...

Sheet I4B
A1: 12.01 | B1: -1.787866 | C1: =EXP(1/F$2*(B1)) -> 0.049172974 | D1: =EXP((Result!H$5+B1-Result!C$29)/F$2) -> 3.2414948e-10 | E1: ave | F1: =AVERAGE(B:B) -> -0.0028606433 | I1: sample_01_12.220000ns | J1: 12.22 | K1: -1845.1222 | L1: -1816.567 | M1: -74.179495 | N1: -45.651298 | O1: -0.02692909 | P1: -16.898259 | Q1: =P1 -> -16.898259
A2: 12.02 | B2: 4.041965 | C2: =EXP(1/F$2*(B2)) -> 907.22232 | D2: =EXP((Result!H$5+B2-Result!C$29)/F$2) -> 5.9804324e-06 | E2: kT(kcal/mol) | F2: 0.5935 | I2: sample_02_13.610000ns | J2: 13.61 | K2: -1860.6732 | L2: -1832.132 | M2: -89.396746 | N2: -60.882162 | O2: -0.026599948 | P2: -16.69172 | Q2: =P2 -> -16.69172
A3: 12.03 | B3: 1.641808 | C3: =EXP(1/F$2*(B3)) -> 15.899936 | D3: =EXP((Result!H$5+B3-Result!C$29)/F$2) -> 1.0481278e-07 | E3: -TDS | F3: =F2*LN(AVERAGE(C:C)) -> 4.0012604 | G3: =F3 -> 4.0012604 | I3: sample_03_15.900000ns | J3: 15.9 | K3: -1865.6684 | L3: -1837.1367 | M3: -94.47459 | N3: -65.965014 | O3: -0.022135348 | P3: -13.89014 | Q3: =P3 -> -13.89014
A4: 12.04 | B4: -1.218353 | C4: =EXP(1/F$2*(B4)) -> 0.12837145 | D4: =EXP((Result!H$5+B4-Result!C$29)/F$2) -> 8.4622781e-10 | E4: dH | F4: =AVERAGE(Q:Q) -> -15.210782 | G4: =AVERAGE(P22:P41) -> -12.910705 | I4: sample_04_17.620000ns | J4: 17.62 | K4: -1870.5969 | L4: -1842.0592 | M4: -99.529699 | N4: -71.016328 | O4: -0.02432306 | P4: -15.26295 | Q4: =P4 -> -15.26295
A5: 12.05 | B5: -1.988517 | C5: =EXP(1/F$2*(B5)) -> 0.035067097 | D5: =EXP((Result!H$5+B5-Result!C$29)/F$2) -> 2.3116319e-10 | I5: sample_05_19.300000ns | J5: 19.3 | K5: -1855.6269 | L5: -1827.0798 | M5: -84.334285 | N5: -55.808924 | O5: -0.021745645 | P5: -13.645598 | Q5: =P5 -> -13.645598
A6: 12.06 | B6: -1.218677 | C6: =EXP(1/F$2*(B6)) -> 0.12830139 | D6: =EXP((Result!H$5+B6-Result!C$29)/F$2) -> 8.4576596e-10 | E6: DG | F6: =SUM(F3:F4) -> -11.209522 | G6: =SUM(G3:G4) -> -8.909445 | I6: sample_06_21.220000ns | J6: 21.22 | K6: -1891.0395 | L6: -1862.4948 | M6: -119.83728 | N6: -91.317631 | O6: -0.025141265 | P6: -15.776382 | Q6: =P6 -> -15.776382
A7: 12.07 | B7: -1.518838 | C7: =EXP(1/F$2*(B7)) -> 0.077372762 | D7: =EXP((Result!H$5+B7-Result!C$29)/F$2) -> 5.100432e-10 | I7: sample_07_23.490000ns | J7: 23.49 | K7: -1860.5554 | L7: -1832.0163 | M7: -89.375445 | N7: -60.858926 | O7: -0.022541952 | P7: -14.145288 | Q7: =P7 -> -14.145288
A8: 12.08 | B8: -0.948987 | C8: =EXP(1/F$2*(B8)) -> 0.20210516 | D8: =EXP((Result!H$5+B8-Result!C$29)/F$2) -> 1.3322823e-09 | I8: sample_08_24.930000ns | J8: 24.93 | K8: -1875.9185 | L8: -1847.374 | M8: -104.61302 | N8: -76.093868 | O8: -0.025347358 | P8: -15.905707 | Q8: =P8 -> -15.905707
A9: 12.09 | B9: 0.750875 | C9: =EXP(1/F$2*(B9)) -> 3.5436748 | D9: =EXP((Result!H$5+B9-Result!C$29)/F$2) -> 2.3359994e-08 | I9: sample_09_27.140000ns | J9: 27.14 | K9: -1885.8698 | L9: -1857.3322 | M9: -114.77985 | N9: -86.262491 | O9: -0.020227745 | P9: -12.693101 | Q9: =P9 -> -12.693101
A10: 12.1 | B10: -2.569258 | C10: =EXP(1/F$2*(B10)) -> 0.013180799 | D10: =EXP((Result!H$5+B10-Result!C$29)/F$2) -> 8.6888161e-11 | E10: =VAR(D:D) -> 8.2122904e-08 | F10: Var(q) | I10: sample_10_29.150000ns | J10: 29.15 | K10: -1875.9574 | L10: -1847.4108 | M10: -104.62412 | N10: -76.10245 | O10: -0.024881792 | P10: -15.61356 | Q10: =P10 -> -15.61356
A11: 12.11 | B11: -0.149385 | C11: =EXP(1/F$2*(B11)) -> 0.77747657 | D11: =EXP((Result!H$5+B11-Result!C$29)/F$2) -> 5.1251451e-09 | I11: sample_11_31.060000ns | J11: 31.06 | K11: -1860.5755 | L11: -1832.0315 | M11: -89.403733 | N11: -60.884102 | O11: -0.0244328 | P11: -15.331814 | Q11: =P11 -> -15.331814
A12: 12.12 | B12: -0.209515 | C12: =EXP(1/F$2*(B12)) -> 0.70256595 | D12: =EXP((Result!H$5+B12-Result!C$29)/F$2) -> 4.6313324e-09 | I12: sample_12_32.190000ns | J12: 32.19 | K12: -1891.1706 | L12: -1862.6358 | M12: -119.8375 | N12: -91.324462 | O12: -0.021749684 | P12: -13.648133 | Q12: =P12 -> -13.648133
A13: 12.13 | B13: -0.999651 | C13: =EXP(1/F$2*(B13)) -> 0.18556836 | D13: =EXP((Result!H$5+B13-Result!C$29)/F$2) -> 1.2232713e-09 | I13: sample_13_34.820000ns | J13: 34.82 | K13: -1860.6095 | L13: -1832.0702 | M13: -89.373984 | N13: -60.858124 | O13: -0.023448601 | P13: -14.714219 | Q13: =P13 -> -14.714219
A14: 12.14 | B14: -1.759784 | C14: =EXP(1/F$2*(B14)) -> 0.051555561 | D14: =EXP((Result!H$5+B14-Result!C$29)/F$2) -> 3.3985556e-10 | I14: sample_14_36.580000ns | J14: 36.58 | K14: -1969.5861 | L14: -1941.3675 | M14: -467.65446 | N14: -439.47142 | O14: -0.035555846 | P14: -22.31163
A15: 12.15 | B15: -1.33992 | C15: =EXP(1/F$2*(B15)) -> 0.10459516 | D15: =EXP((Result!H$5+B15-Result!C$29)/F$2) -> 6.8949396e-10 | I15: sample_15_38.580000ns | J15: 38.58 | K15: -1858.8016 | L15: -1830.2493 | M15: -209.40205 | N15: -180.84407 | O15: 0.0056749355 | P15: 3.561076
A16: 12.16 | B16: 1.159948 | C16: =EXP(1/F$2*(B16)) -> 7.0598199 | D16: =EXP((Result!H$5+B16-Result!C$29)/F$2) -> 4.6538511e-08 | I16: sample_16_40.380000ns | J16: 40.38 | K16: -2251.6967 | L16: -2230.8694 | M16: -561.33768 | N16: -540.52329 | O16: -0.012879463 | P16: -8.081985
A17: 12.17 | B17: -0.110181 | C17: =EXP(1/F$2*(B17)) -> 0.83056743 | D17: =EXP((Result!H$5+B17-Result!C$29)/F$2) -> 5.4751214e-09 | I17: sample_17_42.330000ns | J17: 42.33 | K17: -1870.4525 | L17: -1841.9172 | M17: -99.53154 | N17: -71.020735 | O17: -0.024567343 | P17: -15.41624 | Q17: =P17 -> -15.41624
A18: 12.18 | B18: -0.180312 | C18: =EXP(1/F$2*(B18)) -> 0.73800012 | D18: =EXP((Result!H$5+B18-Result!C$29)/F$2) -> 4.8649154e-09 | I18: sample_18_44.150000ns | J18: 44.15 | K18: -1870.5422 | L18: -1842.0055 | M18: -99.520988 | N18: -71.012104 | O18: -0.027803364 | P18: -17.446874 | Q18: =P18 -> -17.446874
A19: 12.19 | B19: 3.159557 | C19: =EXP(1/F$2*(B19)) -> 205.12113 | D19: =EXP((Result!H$5+B19-Result!C$29)/F$2) -> 1.3521636e-06 | I19: sample_19_46.320000ns | J19: 46.32 | K19: -1860.4821 | L19: -1831.9441 | M19: -89.377876 | N19: -60.865176 | O19: -0.025256465 | P19: -15.848671 | Q19: =P19 -> -15.848671
A20: 12.2 | B20: 1.129437 | C20: =EXP(1/F$2*(B20)) -> 6.7060557 | D20: =EXP((Result!H$5+B20-Result!C$29)/F$2) -> 4.4206488e-08 | I20: sample_20_47.920000ns | J20: 47.92 | K20: -1850.4091 | L20: -1821.8747 | M20: -79.221585 | N20: -50.71219 | O20: -0.024947257 | P20: -15.65464 | Q20: =P20 -> -15.65464
A21: 12.21 | B21: 4.039326 | C21: =EXP(1/F$2*(B21)) -> 903.1973 | D21: =EXP((Result!H$5+B21-Result!C$29)/F$2) -> 5.9538994e-06 | I21: ligand | J21: sample | K21: time_ns | L21: E_protein_ligand_Eh | M21: E_protein_Eh | N21: E_ligand_Eh | O21: DeltaE_Eh | P21: DeltaE_kcal_mol
A22: 12.22 | B22: -0.020778 | C22: =EXP(1/F$2*(B22)) -> 0.96559647 | D22: =EXP((Result!H$5+B22-Result!C$29)/F$2) -> 6.3652362e-09 | I22: IB4 | J22: sample_01_12.220000ns | K22: 12.22 | L22: -1801.2113 | M22: -1772.6596 | N22: -28.529195 | O22: -0.022507031 | P22: -14.123375
A23: 12.23 | B23: 0.119126 | C23: =EXP(1/F$2*(B23)) -> 1.2222798 | D23: =EXP((Result!H$5+B23-Result!C$29)/F$2) -> 8.057299e-09 | I23: IB4 | J23: sample_02_13.610000ns | K23: 13.61 | L23: -1801.5082 | M23: -1772.9711 | N23: -28.515502 | O23: -0.021642753 | P23: -13.581033
A24: 12.24 | B24: -0.750969 | C24: =EXP(1/F$2*(B24)) -> 0.28214824 | D24: =EXP((Result!H$5+B24-Result!C$29)/F$2) -> 1.8599283e-09 | I24: IB4 | J24: sample_03_15.900000ns | K24: 15.9 | L24: -1801.4022 | M24: -1772.8737 | N24: -28.510755 | O24: -0.017754699 | P24: -11.141242
A25: 12.25 | B25: -1.621063 | C25: =EXP(1/F$2*(B25)) -> 0.06513056 | D25: =EXP((Result!H$5+B25-Result!C$29)/F$2) -> 4.2934229e-10 | I25: IB4 | J25: sample_04_17.620000ns | K25: 17.62 | L25: -1801.252 | M25: -1772.7169 | N25: -28.5144 | O25: -0.02072627 | P25: -13.005931
A26: 12.26 | B26: -1.141151 | C26: =EXP(1/F$2*(B26)) -> 0.14620462 | D26: =EXP((Result!H$5+B26-Result!C$29)/F$2) -> 9.6378456e-10 | I26: IB4 | J26: sample_05_19.300000ns | K26: 19.3 | L26: -1801.4868 | M26: -1772.9434 | N26: -28.526344 | O26: -0.017106407 | P26: -10.734433
A27: 12.27 | B27: 1.958767 | C27: =EXP(1/F$2*(B27)) -> 27.122554 | D27: =EXP((Result!H$5+B27-Result!C$29)/F$2) -> 1.7879256e-07 | I27: IB4 | J27: sample_06_21.220000ns | K27: 21.22 | L27: -1801.3353 | M27: -1772.7933 | N27: -28.520294 | O27: -0.021694494 | P27: -13.613501
A28: 12.28 | B28: -0.051325 | C28: =EXP(1/F$2*(B28)) -> 0.91715525 | D28: =EXP((Result!H$5+B28-Result!C$29)/F$2) -> 6.0459105e-09 | I28: IB4 | J28: sample_07_23.490000ns | K28: 23.49 | L28: -1801.3631 | M28: -1772.8267 | N28: -28.517708 | O28: -0.018664986 | P28: -11.712455
A29: 12.29 | B29: 1.878571 | C29: =EXP(1/F$2*(B29)) -> 23.694472 | D29: =EXP((Result!H$5+B29-Result!C$29)/F$2) -> 1.5619456e-07 | I29: IB4 | J29: sample_08_24.930000ns | K29: 24.93 | L29: -1801.4035 | M29: -1772.862 | N29: -28.520163 | O29: -0.021314825 | P29: -13.375254
A30: 12.3 | B30: -2.971538 | C30: =EXP(1/F$2*(B30)) -> 0.0066922596 | D30: =EXP((Result!H$5+B30-Result!C$29)/F$2) -> 4.4115544e-11 | I30: IB4 | J30: sample_09_27.140000ns | K30: 27.14 | L30: -1801.225 | M30: -1772.6899 | N30: -28.517986 | O30: -0.017109099 | P30: -10.736122
A31: 12.31 | B31: -1.561657 | C31: =EXP(1/F$2*(B31)) -> 0.071987192 | D31: =EXP((Result!H$5+B31-Result!C$29)/F$2) -> 4.7454139e-10 | I31: IB4 | J31: sample_10_29.150000ns | K31: 29.15 | L31: -1801.4576 | M31: -1772.9135 | N31: -28.521455 | O31: -0.022689291 | P31: -14.237745
A32: 12.32 | B32: -0.061774 | C32: =EXP(1/F$2*(B32)) -> 0.90114938 | D32: =EXP((Result!H$5+B32-Result!C$29)/F$2) -> 5.9403994e-09 | I32: IB4 | J32: sample_11_31.060000ns | K32: 31.06 | L32: -1801.4242 | M32: -1772.8831 | N32: -28.520749 | O32: -0.020400746 | P32: -12.801661
A33: 12.33 | B33: -1.70189 | C33: =EXP(1/F$2*(B33)) -> 0.056838098 | D33: =EXP((Result!H$5+B33-Result!C$29)/F$2) -> 3.7467817e-10 | I33: IB4 | J33: sample_12_32.190000ns | K33: 32.19 | L33: -1801.4331 | M33: -1772.9016 | N33: -28.513021 | O33: -0.018469472 | P33: -11.589768
... A41: 12.41 | B41: -1.472901 | C41: =EXP(1/F$2*(B41)) -> 0.083599286 | D41: =EXP((Result!H$5+B41-Result!C$29)/F$2) -> 5.510886e-10 | I41: IB4 | J41: sample_20_47.920000ns | K41: 47.92 | L41: -1801.3805 | M41: -1772.8494 | N41: -28.510581 | O41: -0.020502401 | P41: -12.865451
A42: 12.42 | B42: 0.456963 | C42: =EXP(1/F$2*(B42)) -> 2.1596498 | D42: =EXP((Result!H$5+B42-Result!C$29)/F$2) -> 1.4236466e-08
A43: 12.43 | B43: -1.003177 | C43: =EXP(1/F$2*(B43)) -> 0.18446916 | D43: =EXP((Result!H$5+B43-Result!C$29)/F$2) -> 1.2160254e-09
A44: 12.44 | B44: 1.946693 | C44: =EXP(1/F$2*(B44)) -> 26.576355 | D44: =EXP((Result!H$5+B44-Result!C$29)/F$2) -> 1.75192e-07
A45: 12.45 | B45: 2.886574 | C45: =EXP(1/F$2*(B45)) -> 129.4955 | D45: =EXP((Result!H$5+B45-Result!C$29)/F$2) -> 8.5363763e-07
A46: 12.46 | B46: 2.146459 | C46: =EXP(1/F$2*(B46)) -> 37.211268 | D46: =EXP((Result!H$5+B46-Result!C$29)/F$2) -> 2.4529762e-07
A47: 12.47 | B47: 0.37635 | C47: =EXP(1/F$2*(B47)) -> 1.8853616 | D47: =EXP((Result!H$5+B47-Result!C$29)/F$2) -> 1.2428351e-08
...

Sheet IND
A1: 12.01 | B1: 1.639011 | C1: =EXP(1/F$2*(B1)) -> 15.82518 | D1: =EXP((Result!H$6+B1-Result!C$30)/F$2) -> 8.5979918e-05 | E1: ave | F1: =AVERAGE(B:B) -> -0.0081970161 | I1: sample_01_12.750000ns | J1: 12.75 | K1: -1870.5483 | L1: -1846.9242 | M1: -99.716074 | N1: -76.122064 | O1: -0.030137186 | P1: -18.91137 | Q1: =P1 -> -18.91137
A2: 12.02 | B2: 2.748939 | C2: =EXP(1/F$2*(B2)) -> 102.69282 | D2: =EXP((Result!H$6+B2-Result!C$30)/F$2) -> 0.00055794122 | E2: kT(kcal/mol) | F2: 0.5935 | I2: sample_02_14.130000ns | J2: 14.13 | K2: -1881.0984 | L2: -1857.4764 | M2: -119.94038 | N2: -96.347113 | O2: -0.028725668 | P2: -18.025629 | Q2: =P2 -> -18.025629
A3: 12.03 | B3: -0.161397 | C3: =EXP(1/F$2*(B3)) -> 0.76189919 | D3: =EXP((Result!H$6+B3-Result!C$30)/F$2) -> 4.1394808e-06 | E3: -TDS | F3: =F2*LN(AVERAGE(C:C)) -> 3.7577405 | G3: =F3 -> 3.7577405 | I3: sample_03_15.860000ns | J3: 15.86 | K3: -2046.7134 | L3: -2023.0392 | M3: -335.40423 | N3: -311.76213 | O3: -0.032118613 | P3: -20.154734 | Q3: =P3 -> -20.154734
A4: 12.04 | B4: 2.578323 | C4: =EXP(1/F$2*(B4)) -> 77.035619 | D4: =EXP((Result!H$6+B4-Result!C$30)/F$2) -> 0.00041854286 | E4: dH | F4: =AVERAGE(Q:Q) -> -17.791162 | G4: =AVERAGE(P22:P41) -> -11.873989 | I4: sample_04_17.720000ns | J4: 17.72 | K4: -1945.1818 | L4: -1921.5556 | M4: -204.00681 | N4: -180.34942 | O4: 0.031208283 | P4: 19.583493
A5: 12.05 | B5: 3.498095 | C5: =EXP(1/F$2*(B5)) -> 362.85747 | D5: =EXP((Result!H$6+B5-Result!C$30)/F$2) -> 0.0019714439 | I5: sample_05_19.800000ns | J5: 19.8 | K5: -1865.745 | L5: -1842.1257 | M5: -94.633176 | N5: -71.050402 | O5: -0.03653559 | P5: -22.926429 | Q5: =P5 -> -22.926429
A6: 12.06 | B6: 0.837781 | C6: =EXP(1/F$2*(B6)) -> 4.1024893 | D6: =EXP((Result!H$6+B6-Result!C$30)/F$2) -> 2.2289269e-05 | E6: DG | F6: =SUM(F3:F4) -> -14.033422 | G6: =SUM(G3:G4) -> -8.1162489 | I6: sample_06_21.480000ns | J6: 21.48 | K6: -1874.5732 | L6: -1850.9469 | M6: -120.00791 | N6: -96.413261 | O6: -0.031658638 | P6: -19.866095 | Q6: =P6 -> -19.866095
A7: 12.07 | B7: 0.647456 | C7: =EXP(1/F$2*(B7)) -> 2.9769865 | D7: =EXP((Result!H$6+B7-Result!C$30)/F$2) -> 1.617429e-05 | I7: sample_07_23.400000ns | J7: 23.4 | K7: -1835.1907 | L7: -1811.5707 | M7: -64.174689 | N7: -40.58261 | O7: -0.027847423 | P7: -17.474522 | Q7: =P7 -> -17.474522
A8: 12.08 | B8: 2.026873 | C8: =EXP(1/F$2*(B8)) -> 30.420563 | D8: =EXP((Result!H$6+B8-Result!C$30)/F$2) -> 0.00016527821 | I8: sample_08_25.340000ns | J8: 25.34 | K8: -1850.3684 | L8: -1826.7357 | M8: -79.402422 | N8: -55.802027 | O8: -0.032289268 | P8: -20.261821 | Q8: =P8 -> -20.261821
A9: 12.09 | B9: 3.866009 | C9: =EXP(1/F$2*(B9)) -> 674.46228 | D9: =EXP((Result!H$6+B9-Result!C$30)/F$2) -> 0.0036644266 | I9: sample_09_27.180000ns | J9: 27.18 | K9: -1873.9613 | L9: -1850.3348 | M9: -102.69712 | N9: -79.028654 | O9: 0.04189584 | P9: 26.290037
A10: 12.1 | B10: 1.775046 | C10: =EXP(1/F$2*(B10)) -> 19.901805 | D10: =EXP((Result!H$6+B10-Result!C$30)/F$2) -> 0.00010812866 | E10: =VAR(D:D) -> 0.0098984967 | F10: Var(q) | I10: sample_10_29.230000ns | J10: 29.23 | K10: -1850.4486 | L10: -1826.8349 | M10: -79.40149 | N10: -55.808975 | O10: -0.021138034 | P10: -13.264316 | Q10: =P10 -> -13.264316
A11: 12.11 | B11: 5.853925 | C11: =EXP(1/F$2*(B11)) -> 19214.013 | D11: =EXP((Result!H$6+B11-Result!C$30)/F$2) -> 0.10439181 | I11: sample_11_31.180000ns | J11: 31.18 | K11: -1825.1044 | L11: -1801.4916 | M11: -54.026635 | N11: -30.436382 | O11: -0.02252063 | P11: -14.131909 | Q11: =P11 -> -14.131909
A12: 12.12 | B12: 3.032859 | C12: =EXP(1/F$2*(B12)) -> 165.69101 | D12: =EXP((Result!H$6+B12-Result!C$30)/F$2) -> 0.00090021722 | I12: sample_12_32.860000ns | J12: 32.86 | K12: -1835.3303 | L12: -1811.7111 | M12: -64.186237 | N12: -40.595137 | O12: -0.028075826 | P12: -17.617847 | Q12: =P12 -> -17.617847
A13: 12.13 | B13: 4.501885 | C13: =EXP(1/F$2*(B13)) -> 1969.0686 | D13: =EXP((Result!H$6+B13-Result!C$30)/F$2) -> 0.010698163 | I13: sample_13_34.760000ns | J13: 34.76 | K13: -1835.3762 | L13: -1811.7647 | M13: -64.17118 | N13: -40.587177 | O13: -0.027501081 | P13: -17.257189 | Q13: =P13 -> -17.257189
A14: 12.14 | B14: -0.889143 | C14: =EXP(1/F$2*(B14)) -> 0.22354673 | D14: =EXP((Result!H$6+B14-Result!C$30)/F$2) -> 1.2145536e-06 | I14: sample_14_36.480000ns | J14: 36.48 | K14: -1883.3953 | L14: -1859.7736 | M14: -150.43465 | N14: -126.84143 | O14: -0.028523202 | P14: -17.898579 | Q14: =P14 -> -17.898579
A15: 12.15 | B15: 2.06984 | C15: =EXP(1/F$2*(B15)) -> 32.704567 | D15: =EXP((Result!H$6+B15-Result!C$30)/F$2) -> 0.00017768746 | I15: sample_15_38.520000ns | J15: 38.52 | K15: -1982.3701 | L15: -1958.7196 | M15: -266.32889 | N15: -242.66615 | O15: 0.012275475 | P15: 7.702977
A16: 12.16 | B16: -1.871254 | C16: =EXP(1/F$2*(B16)) -> 0.042727471 | D16: =EXP((Result!H$6+B16-Result!C$30)/F$2) -> 2.3214297e-07 | I16: sample_16_40.400000ns | J16: 40.4 | K16: -1825.0376 | L16: -1801.4139 | M16: -54.025027 | N16: -30.429626 | O16: -0.028307716 | P16: -17.76336 | Q16: =P16 -> -17.76336
A17: 12.17 | B17: -0.862435 | C17: =EXP(1/F$2*(B17)) -> 0.23383631 | D17: =EXP((Result!H$6+B17-Result!C$30)/F$2) -> 1.270458e-06 | I17: sample_17_42.390000ns | J17: 42.39 | K17: -1825.1946 | L17: -1801.5706 | M17: -54.026978 | N17: -30.427008 | O17: -0.024003091 | P17: -15.062167 | Q17: =P17 -> -15.062167
A18: 12.18 | B18: -2.813604 | C18: =EXP(1/F$2*(B18)) -> 0.0087325526 | D18: =EXP((Result!H$6+B18-Result!C$30)/F$2) -> 4.7444904e-08 | I18: sample_18_44.160000ns | J18: 44.16 | K18: -1826.0832 | L18: -1802.461 | M18: -59.090178 | N18: -35.493073 | O18: -0.025086034 | P18: -15.741724 | Q18: =P18 -> -15.741724
A19: 12.19 | B19: -4.40478 | C19: =EXP(1/F$2*(B19)) -> 0.0005981304 | D19: =EXP((Result!H$6+B19-Result!C$30)/F$2) -> 3.2497072e-09 | I19: sample_19_45.890000ns | J19: 45.89 | K19: -1820.144 | L19: -1796.5221 | M19: -48.950925 | N19: -25.356887 | O19: -0.027789879 | P19: -17.438412 | Q19: =P19 -> -17.438412
A20: 12.2 | B20: 1.183809 | C20: =EXP(1/F$2*(B20)) -> 7.3494349 | D20: =EXP((Result!H$6+B20-Result!C$30)/F$2) -> 3.9930276e-05 | I20: sample_20_47.500000ns | J20: 47.5 | K20: -1825.1127 | L20: -1801.4855 | M20: -54.024718 | N20: -30.427299 | O20: -0.029726488 | P20: -18.653653 | Q20: =P20 -> -18.653653
A21: 12.21 | B21: -2.257845 | C21: =EXP(1/F$2*(B21)) -> 0.022275049 | D21: =EXP((Result!H$6+B21-Result!C$30)/F$2) -> 1.2102275e-07 | I21: ligand | J21: sample | K21: time_ns | L21: E_protein_ligand_Eh | M21: E_protein_Eh | N21: E_ligand_Eh | O21: DeltaE_Eh | P21: DeltaE_kcal_mol
A22: 12.22 | B22: -1.419642 | C22: =EXP(1/F$2*(B22)) -> 0.091448148 | D22: =EXP((Result!H$6+B22-Result!C$30)/F$2) -> 4.9684769e-07 | I22: IND | J22: sample_01_12.210000ns | K22: 12.21 | L22: -1876.4488 | M22: -1852.8165 | N22: -23.609224 | O22: -0.023080008 | P22: -14.482924
A23: 12.23 | B23: -1.821642 | C23: =EXP(1/F$2*(B23)) -> 0.046452687 | D23: =EXP((Result!H$6+B23-Result!C$30)/F$2) -> 2.5238248e-07 | I23: IND | J23: sample_02_13.830000ns | K23: 13.83 | L23: -1796.4444 | M23: -1772.8258 | N23: -23.603337 | O23: -0.015252226 | P23: -9.570916
A24: 12.24 | B24: -2.693686 | C24: =EXP(1/F$2*(B24)) -> 0.010687875 | D24: =EXP((Result!H$6+B24-Result!C$30)/F$2) -> 5.8068384e-08 | I24: IND | J24: sample_03_15.860000ns | K24: 15.86 | L24: -1796.4523 | M24: -1772.8289 | N24: -23.603615 | O24: -0.019735499 | P24: -12.384213
A25: 12.25 | B25: -1.335762 | C25: =EXP(1/F$2*(B25)) -> 0.10533052 | D25: =EXP((Result!H$6+B25-Result!C$30)/F$2) -> 5.7227212e-07 | I25: IND | J25: sample_04_17.630000ns | K25: 17.63 | L25: -1796.3575 | M25: -1772.7468 | N25: -23.589574 | O25: -0.021159312 | P25: -13.277669
A26: 12.26 | B26: -1.478001 | C26: =EXP(1/F$2*(B26)) -> 0.082883987 | D26: =EXP((Result!H$6+B26-Result!C$30)/F$2) -> 4.5031768e-07 | I26: IND | J26: sample_05_19.550000ns | K26: 19.55 | L26: -1796.5244 | M26: -1772.9156 | N26: -23.586322 | O26: -0.022502117 | P26: -14.120292
A27: 12.27 | B27: 1.249633 | C27: =EXP(1/F$2*(B27)) -> 8.211467 | D27: =EXP((Result!H$6+B27-Result!C$30)/F$2) -> 4.4613789e-05 | I27: IND | J27: sample_06_21.310000ns | K27: 21.31 | L27: -1796.2032 | M27: -1772.5847 | N27: -23.598792 | O27: -0.019787835 | P27: -12.417054
A28: 12.28 | B28: -0.912519 | C28: =EXP(1/F$2*(B28)) -> 0.21491311 | D28: =EXP((Result!H$6+B28-Result!C$30)/F$2) -> 1.1676462e-06 | I28: IND | J28: sample_07_23.480000ns | K28: 23.48 | L28: -1796.3885 | M28: -1772.7877 | N28: -23.581929 | O28: -0.018875249 | P28: -11.844398
A29: 12.29 | B29: -3.834439 | C29: =EXP(1/F$2*(B29)) -> 0.001563665 | D29: =EXP((Result!H$6+B29-Result!C$30)/F$2) -> 8.4955615e-09 | I29: IND | J29: sample_08_25.290000ns | K29: 25.29 | L29: -1796.4815 | M29: -1772.8599 | N29: -23.599038 | O29: -0.022582181 | P29: -14.170532
A30: 12.3 | B30: -3.346261 | C30: =EXP(1/F$2*(B30)) -> 0.0035593335 | D30: =EXP((Result!H$6+B30-Result!C$30)/F$2) -> 1.9338244e-08 | I30: IND | J30: sample_09_26.920000ns | K30: 26.92 | L30: -1796.4315 | M30: -1772.8253 | N30: -23.586807 | O30: -0.019326787 | P30: -12.127742
A31: 12.31 | B31: -3.277892 | C31: =EXP(1/F$2*(B31)) -> 0.0039939056 | D31: =EXP((Result!H$6+B31-Result!C$30)/F$2) -> 2.1699322e-08 | I31: IND | J31: sample_10_29.150000ns | K31: 29.15 | L31: -1796.4656 | M31: -1772.8426 | N31: -23.604852 | O31: -0.018145206 | P31: -11.386289
A32: 12.32 | B32: -1.589561 | C32: =EXP(1/F$2*(B32)) -> 0.068680974 | D32: =EXP((Result!H$6+B32-Result!C$30)/F$2) -> 3.7315117e-07 | I32: IND | J32: sample_11_31.130000ns | K32: 31.13 | L32: -1796.3817 | M32: -1772.7702 | N32: -23.595031 | O32: -0.016468525 | P32: -10.334155
A33: 12.33 | B33: -4.951274 | C33: =EXP(1/F$2*(B33)) -> 0.00023817606 | D33: =EXP((Result!H$6+B33-Result!C$30)/F$2) -> 1.2940363e-09 | I33: IND | J33: sample_12_32.890000ns | K33: 32.89 | L33: -1796.3375 | M33: -1772.7269 | N33: -23.596014 | O33: -0.014591864 | P33: -9.156533
... A41: 12.41 | B41: -1.913696 | C41: =EXP(1/F$2*(B41)) -> 0.039778664 | D41: =EXP((Result!H$6+B41-Result!C$30)/F$2) -> 2.1612179e-07 | I41: IND | J41: sample_20_47.970000ns | K41: 47.97 | L41: -1796.4653 | M41: -1772.8473 | N41: -23.599092 | O41: -0.018852623 | P41: -11.8302
A42: 12.42 | B42: -1.965099 | C42: =EXP(1/F$2*(B42)) -> 0.036478416 | D42: =EXP((Result!H$6+B42-Result!C$30)/F$2) -> 1.9819118e-07
A43: 12.43 | B43: 0.743553 | C43: =EXP(1/F$2*(B43)) -> 3.5002252 | D43: =EXP((Result!H$6+B43-Result!C$30)/F$2) -> 1.9017102e-05
A44: 12.44 | B44: 0.611986 | C44: =EXP(1/F$2*(B44)) -> 2.8042817 | D44: =EXP((Result!H$6+B44-Result!C$30)/F$2) -> 1.5235966e-05
A45: 12.45 | B45: -3.169837 | C45: =EXP(1/F$2*(B45)) -> 0.0047914526 | D45: =EXP((Result!H$6+B45-Result!C$30)/F$2) -> 2.6032481e-08
A46: 12.46 | B46: -0.251756 | C46: =EXP(1/F$2*(B46)) -> 0.6543004 | D46: =EXP((Result!H$6+B46-Result!C$30)/F$2) -> 3.5548849e-06
A47: 12.47 | B47: 0.816149 | C47: =EXP(1/F$2*(B47)) -> 3.9556532 | D47: =EXP((Result!H$6+B47-Result!C$30)/F$2) -> 2.1491492e-05
...

Sheet N4B
A1: 12.01 | B1: -1.309923 | C1: =EXP(1/F$2*(B1)) -> 0.11001755 | D1: =EXP((Result!H$7+B1-Result!C$31)/F$2) -> 5.5386074e-10 | E1: ave | F1: =AVERAGE(B:B) -> 0.0012147133 | I1: sample_01_12.550000ns | J1: 12.55 | K1: -2221.153 | L1: -2202.8552 | M1: -684.07136 | N1: -665.79444 | O1: -0.020887179 | P1: -13.106903 | Q1: =P1 -> -13.106903
A2: 12.02 | B2: -0.66 | C2: =EXP(1/F$2*(B2)) -> 0.32888499 | D2: =EXP((Result!H$7+B2-Result!C$31)/F$2) -> 1.6557039e-09 | E2: kT(kcal/mol) | F2: 0.5935 | I2: sample_02_13.950000ns | J2: 13.95 | K2: -2212.5315 | L2: -2204.9085 | M2: -707.53478 | N2: -699.97098 | O2: -0.059199303 | P2: -37.148123
A3: 12.03 | B3: 0.13006 | C3: =EXP(1/F$2*(B3)) -> 1.2450064 | D3: =EXP((Result!H$7+B3-Result!C$31)/F$2) -> 6.2677291e-09 | E3: -TDS | F3: =F2*LN(AVERAGE(C:C)) -> 3.425884 | G3: =F3 -> 3.425884 | I3: sample_03_15.850000ns | J3: 15.85 | K3: -2203.3291 | L3: -2175.5433 | M3: -619.39874 | N3: -591.62605 | O3: -0.013076495 | P3: -8.205624
A4: 12.04 | B4: 2.050088 | C4: =EXP(1/F$2*(B4)) -> 31.634054 | D4: =EXP((Result!H$7+B4-Result!C$31)/F$2) -> 1.5925515e-07 | E4: dH | F4: =AVERAGE(Q:Q) -> -16.023794 | G4: =AVERAGE(P22:P41) -> -13.733508 | I4: sample_04_17.910000ns | J4: 17.91 | K4: -1855.4103 | L4: -1826.8694 | M4: -84.318325 | N4: -55.802535 | O4: -0.025096452 | P4: -15.748261 | Q4: =P4 -> -15.748261
A5: 12.05 | B5: 2.880088 | C5: =EXP(1/F$2*(B5)) -> 128.08803 | D5: =EXP((Result!H$7+B5-Result!C$31)/F$2) -> 6.4483289e-07 | I5: sample_05_19.470000ns | J5: 19.47 | K5: -1984.6526 | L5: -1956.1066 | M5: -307.74165 | N5: -279.22958 | O5: -0.033965317 | P5: -21.313558 | Q5: =P5 -> -21.313558
A6: 12.06 | B6: 0.99013 | C6: =EXP(1/F$2*(B6)) -> 5.3030907 | D6: =EXP((Result!H$7+B6-Result!C$31)/F$2) -> 2.6697321e-08 | E6: DG | F6: =SUM(F3:F4) -> -12.59791 | G6: =SUM(G3:G4) -> -10.307624 | I6: sample_06_21.390000ns | J6: 21.39 | K6: -1844.8348 | L6: -1816.287 | M6: -74.167702 | N6: -45.645445 | O6: -0.025534267 | P6: -16.022995 | Q6: =P6 -> -16.022995
A7: 12.07 | B7: 1.350177 | C7: =EXP(1/F$2*(B7)) -> 9.7273372 | D7: =EXP((Result!H$7+B7-Result!C$31)/F$2) -> 4.8970281e-08 | I7: sample_07_23.360000ns | J7: 23.36 | K7: -1901.2715 | L7: -1872.7252 | M7: -130.02171 | N7: -101.50347 | O7: -0.028090714 | P7: -17.627189 | Q7: =P7 -> -17.627189
A8: 12.08 | B8: 1.450355 | C8: =EXP(1/F$2*(B8)) -> 11.515939 | D8: =EXP((Result!H$7+B8-Result!C$31)/F$2) -> 5.7974631e-08 | I8: sample_08_25.210000ns | J8: 25.21 | K8: -2206.5884 | L8: -2185.5944 | M8: -637.67116 | N8: -616.81288 | O8: -0.13574988 | P8: -85.184334
A9: 12.09 | B9: -0.109322 | C9: =EXP(1/F$2*(B9)) -> 0.83177041 | D9: =EXP((Result!H$7+B9-Result!C$31)/F$2) -> 4.1873773e-09 | I9: sample_09_27.020000ns | J9: 27.02 | K9: -1765.5177 | L9: -1736.9783 | M9: -129.9381 | N9: -101.42202 | O9: -0.023324369 | P9: -14.636263 | Q9: =P9 -> -14.636263
A10: 12.1 | B10: -1.30895 | C10: =EXP(1/F$2*(B10)) -> 0.11019806 | D10: =EXP((Result!H$7+B10-Result!C$31)/F$2) -> 5.547695e-10 | E10: =VAR(D:D) -> 3.1444567e-09 | F10: Var(q) | I10: sample_10_28.990000ns | J10: 28.99 | K10: -1906.4905 | L10: -1877.954 | M10: -135.0688 | N10: -106.55678 | O10: -0.024513967 | P10: -15.382746 | Q10: =P10 -> -15.382746
A11: 12.11 | B11: 0.101502 | C11: =EXP(1/F$2*(B11)) -> 1.1865177 | D11: =EXP((Result!H$7+B11-Result!C$31)/F$2) -> 5.9732799e-09 | I11: sample_11_30.840000ns | J11: 30.84 | K11: -1885.7609 | L11: -1857.2195 | M11: -114.78491 | N11: -86.268706 | O11: -0.025211956 | P11: -15.820741 | Q11: =P11 -> -15.820741
A12: 12.12 | B12: 2.941924 | C12: =EXP(1/F$2*(B12)) -> 142.15336 | D12: =EXP((Result!H$7+B12-Result!C$31)/F$2) -> 7.156419e-07 | I12: sample_12_32.780000ns | J12: 32.78 | K12: -1890.7788 | L12: -1862.231 | M12: -119.84676 | N12: -91.326338 | O12: -0.027362619 | P12: -17.170303 | Q12: =P12 -> -17.170303
A13: 12.13 | B13: -0.417705 | C13: =EXP(1/F$2*(B13)) -> 0.49470211 | D13: =EXP((Result!H$7+B13-Result!C$31)/F$2) -> 2.4904762e-09 | I13: sample_13_34.810000ns | J13: 34.81 | K13: -1870.7591 | L13: -1842.2206 | M13: -99.53818 | N13: -71.022755 | O13: -0.023061495 | P13: -14.471307 | Q13: =P13 -> -14.471307
A14: 12.14 | B14: -1.677309 | C14: =EXP(1/F$2*(B14)) -> 0.059241592 | D14: =EXP((Result!H$7+B14-Result!C$31)/F$2) -> 2.9823963e-10 | I14: sample_14_36.760000ns | J14: 36.76 | K14: -1891.1205 | L14: -1862.5885 | M14: -119.83596 | N14: -91.324981 | O14: -0.020925672 | P14: -13.131057 | Q14: =P14 -> -13.131057
A15: 12.15 | B15: -1.136919 | C15: =EXP(1/F$2*(B15)) -> 0.14725087 | D15: =EXP((Result!H$7+B15-Result!C$31)/F$2) -> 7.4130428e-10 | I15: sample_15_38.680000ns | J15: 38.68 | K15: -1870.4695 | L15: -1841.928 | M15: -99.5255 | N15: -71.008566 | O15: -0.024518146 | P15: -15.385369 | Q15: =P15 -> -15.385369
A16: 12.16 | B16: -0.406493 | C16: =EXP(1/F$2*(B16)) -> 0.50413652 | D16: =EXP((Result!H$7+B16-Result!C$31)/F$2) -> 2.5379718e-09 | I16: sample_16_40.360000ns | J16: 40.36 | K16: -1921.1224 | L16: -1892.5757 | M16: -190.9824 | N16: -162.46186 | O16: -0.0261894 | P16: -16.434097 | Q16: =P16 -> -16.434097
A17: 12.17 | B17: -2.046023 | C17: =EXP(1/F$2*(B17)) -> 0.03182876 | D17: =EXP((Result!H$7+B17-Result!C$31)/F$2) -> 1.6023535e-10 | I17: sample_17_42.380000ns | J17: 42.38 | K17: -1891.1465 | L17: -1862.6158 | M17: -119.83945 | N17: -91.333824 | O17: -0.025098131 | P17: -15.749315 | Q17: =P17 -> -15.749315
